<?xml version="0.0" ?>
<robot name="humanoid">
	<link name="world"/>
	<link name="aux_pitch">
		<inertial>
			<origin rpy="0.00000 -0.00000 0.00000" xyz="0.00000 0.00000 0.00000"/>
			<mass value="0.0"/>
			<inertia ixx="0.0" ixy="0" ixz="0" iyy="0.0" iyz="0" izz="0.0"/>
		</inertial>
	</link>
	<link name="aux_roll">
		<inertial>
			<origin rpy="0.00000 -0.00000 0.00000" xyz="0.00000 0.00000 0.00000"/>
			<mass value="0.0"/>
			<inertia ixx="0.0" ixy="0" ixz="0" iyy="0.0" iyz="0" izz="0.0"/>
		</inertial>
	</link>
	<link name="aux_yaw">
		<inertial>
			<origin rpy="0.00000 -0.00000 0.00000" xyz="0.00000 0.00000 0.00000"/>
			<mass value="0.0"/>
			<inertia ixx="0.0" ixy="0" ixz="0" iyy="0.0" iyz="0" izz="0.0"/>
		</inertial>
	</link>
	<link name="aux_x">
		<inertial>
			<origin rpy="0.00000 -0.00000 0.00000" xyz="0.00000 0.00000 0.00000"/>
			<mass value="0.0"/>
			<inertia ixx="0.0" ixy="0" ixz="0" iyy="0.0" iyz="0" izz="0.0"/>
		</inertial>
	</link>
	<link name="aux_y">
		<inertial>
			<origin rpy="0.00000 -0.00000 0.00000" xyz="0.00000 0.00000 0.00000"/>
			<mass value="0.0"/>
			<inertia ixx="0.0" ixy="0" ixz="0" iyy="0.0" iyz="0" izz="0.0"/>
		</inertial>
	</link>
	<link name="root">
		<inertial>
			<origin rpy="0.00000 -0.00000 0.00000" xyz="0.00000 0.00000 0.00000"/>
			<mass value="5.57527976"/>
			<inertia ixx="0.04497" ixy="0" ixz="0" iyy="0.04497" iyz="0" izz="0.04497"/>
		</inertial>
		<collision>
			<origin rpy="0.00000 -0.00000 0.00000" xyz="0.00000 0.00000 -0.02400"/>
			<geometry>
				<sphere radius="0.11000"/>
			</geometry>
		</collision>
		<visual>
			<origin rpy="0.00000 -0.00000 0.00000" xyz="0.00000 0.00000 -0.02400"/>
			<geometry>
				<sphere radius="0.11000"/>
			</geometry>
		</visual>
	</link>
	<link name="lhipjoint">
		<inertial>
			<origin rpy="0.00000 -0.00000 0.00000" xyz="0.00000 0.00000 0.00000"/>
			<mass value="0.001"/>
			<inertia ixx="0.001" ixy="0" ixz="0" iyy="0.001" iyz="0" izz="0.001"/>
		</inertial>
	</link>
	<link name="link1_3">
		<inertial>
			<origin rpy="0.00000 -0.00000 0.00000" xyz="0.00000 0.00000 0.00000"/>
			<mass value="0.001"/>
			<inertia ixx="0.001" ixy="0" ixz="0" iyy="0.001" iyz="0" izz="0.001"/>
		</inertial>
	</link>
	<link name="link1_4">
		<inertial>
			<origin rpy="0.00000 -0.00000 0.00000" xyz="0.00000 0.00000 0.00000"/>
			<mass value="0.001"/>
			<inertia ixx="0.001" ixy="0" ixz="0" iyy="0.001" iyz="0" izz="0.001"/>
		</inertial>
	</link>
	<link name="lfemur">
		<inertial>
			<origin rpy="0.00000 -0.00000 0.00000" xyz="0.00000 0.00000 0.00000"/>
			<mass value="3.35909109"/>
			<inertia ixx="0.06392" ixy="0" ixz="0" iyy="0.07914" iyz="0" izz="0.02154"/>
		</inertial>
		<!-- <collision>
			<origin rpy="0.00000 -0.34919 0.00000" xyz="0.06555 0.00000 -0.18015"/>
			<geometry>
				<capsule length="0.34343" radius="0.05200"/>
			</geometry>
		</collision> -->
		<visual>
			<origin rpy="0.00000 -0.34919 0.00000" xyz="0.06555 0.00000 -0.18015"/>
			<geometry>
				<capsule length="0.34343" radius="0.05200"/>
			</geometry>
		</visual>
	</link>
	<link name="ltibia">
		<inertial>
			<origin rpy="0.00000 -0.00000 0.00000" xyz="0.00000 0.00000 0.00000"/>
			<mass value="1.72621109"/>
			<inertia ixx="0.02916" ixy="0" ixz="0" iyy="0.03549" iyz="0" izz="0.00795"/>
		</inertial>
		<!-- <collision>
			<origin rpy="0.00000 -0.34900 0.00000" xyz="0.06920 0.00000 -0.19000"/>
			<geometry>
				<capsule length="0.36437" radius="0.03700"/>
			</geometry>
		</collision> -->
		<visual>
			<origin rpy="0.00000 -0.34900 0.00000" xyz="0.06920 0.00000 -0.19000"/>
			<geometry>
				<capsule length="0.36437" radius="0.03700"/>
			</geometry>
		</visual>
	</link>
	<link name="link1_9">
		<inertial>
			<origin rpy="0.00000 -0.00000 0.00000" xyz="0.00000 0.00000 0.00000"/>
			<mass value="0.001"/>
			<inertia ixx="0.001" ixy="0" ixz="0" iyy="0.001" iyz="0" izz="0.001"/>
		</inertial>
	</link>
	<link name="link1_10">
		<inertial>
			<origin rpy="0.00000 -0.00000 0.00000" xyz="0.00000 0.00000 0.00000"/>
			<mass value="0.001"/>
			<inertia ixx="0.001" ixy="0" ixz="0" iyy="0.001" iyz="0" izz="0.001"/>
		</inertial>
	</link>
	<link name="lfoot">
		<inertial>
			<origin rpy="0.00000 -0.00000 0.00000" xyz="0.00000 0.00000 0.00000"/>
			<mass value="2.14466058"/>
			<inertia ixx="0.00547" ixy="0" ixz="0" iyy="0.00248" iyz="0" izz="0.00642"/>
		</inertial>
		<collision>
			<origin rpy="0.00000 -0.34897 0.00000" xyz="0.00570 -0.04960 -0.01210"/>
			<geometry>
				<box size="0.12000 0.21400 0.04800"/>
				<!-- <box size="0.16000 0.31400 0.04800"/> -->
				<!-- <sphere radius="0.08"/> -->
			</geometry>
		</collision>
		<visual>
			<origin rpy="0.00000 -0.34897 0.00000" xyz="0.00570 -0.04960 -0.01210"/>
			<geometry>
				<box size="0.12000 0.21400 0.04800"/>
				<!-- <box size="0.16000 0.31400 0.04800"/> -->
				<!-- <sphere radius="0.08"/> -->
			</geometry>
		</visual>
	</link>
	<link name="rhipjoint">
		<inertial>
			<origin rpy="0.00000 -0.00000 0.00000" xyz="0.00000 0.00000 0.00000"/>
			<mass value="0.001"/>
			<inertia ixx="0.001" ixy="0" ixz="0" iyy="0.001" iyz="0" izz="0.001"/>
		</inertial>
	</link>
	<link name="link1_14">
		<inertial>
			<origin rpy="0.00000 -0.00000 0.00000" xyz="0.00000 0.00000 0.00000"/>
			<mass value="0.001"/>
			<inertia ixx="0.001" ixy="0" ixz="0" iyy="0.001" iyz="0" izz="0.001"/>
		</inertial>
	</link>
	<link name="link1_15">
		<inertial>
			<origin rpy="0.00000 -0.00000 0.00000" xyz="0.00000 0.00000 0.00000"/>
			<mass value="0.001"/>
			<inertia ixx="0.001" ixy="0" ixz="0" iyy="0.001" iyz="0" izz="0.001"/>
		</inertial>
	</link>
	<link name="rfemur">
		<inertial>
			<origin rpy="0.00000 -0.00000 0.00000" xyz="0.00000 0.00000 0.00000"/>
			<mass value="3.35909109"/>
			<inertia ixx="0.06392" ixy="0" ixz="0" iyy="0.07914" iyz="0" izz="0.02154"/>
		</inertial>
		<!-- <collision>
			<origin rpy="0.00000 0.34919 0.00000" xyz="-0.06555 0.00000 -0.18015"/>
			<geometry>
				<capsule length="0.34343" radius="0.05200"/>
			</geometry>
		</collision> -->
		<visual>
			<origin rpy="0.00000 0.34919 0.00000" xyz="-0.06555 0.00000 -0.18015"/>
			<geometry>
				<capsule length="0.34343" radius="0.05200"/>
			</geometry>
		</visual>
	</link>
	<link name="rtibia">
		<inertial>
			<origin rpy="0.00000 -0.00000 0.00000" xyz="0.00000 0.00000 0.00000"/>
			<mass value="1.72621109"/>
			<inertia ixx="0.02916" ixy="0" ixz="0" iyy="0.03549" iyz="0" izz="0.00795"/>
		</inertial>
		<!-- <collision>
			<origin rpy="0.00000 0.34900 0.00000" xyz="-0.06920 0.00000 -0.19000"/>
			<geometry>
				<capsule length="0.36437" radius="0.03700"/>
			</geometry>
		</collision> -->
		<visual>
			<origin rpy="0.00000 0.34900 0.00000" xyz="-0.06920 0.00000 -0.19000"/>
			<geometry>
				<capsule length="0.36437" radius="0.03700"/>
			</geometry>
		</visual>
	</link>
	<link name="link1_20">
		<inertial>
			<origin rpy="0.00000 -0.00000 0.00000" xyz="0.00000 0.00000 0.00000"/>
			<mass value="0.001"/>
			<inertia ixx="0.001" ixy="0" ixz="0" iyy="0.001" iyz="0" izz="0.001"/>
		</inertial>
	</link>
	<link name="link1_21">
		<inertial>
			<origin rpy="0.00000 -0.00000 0.00000" xyz="0.00000 0.00000 0.00000"/>
			<mass value="0.001"/>
			<inertia ixx="0.001" ixy="0" ixz="0" iyy="0.001" iyz="0" izz="0.001"/>
		</inertial>
	</link>
	<link name="rfoot">
		<inertial>
			<origin rpy="0.00000 -0.00000 0.00000" xyz="0.00000 0.00000 0.00000"/>
			<mass value="2.14466058"/>
			<inertia ixx="0.00547" ixy="0" ixz="0" iyy="0.00248" iyz="0" izz="0.00642"/>
		</inertial>
		<collision>
			<origin rpy="0.00000 0.34897 0.00000" xyz="-0.00570 -0.04960 -0.01210"/>
			<geometry>
				<box size="0.12000 0.21400 0.04800"/>
				<!-- <box size="0.16000 0.31400 0.04800"/> -->
				<!-- <sphere radius="0.08"/> -->
			</geometry>
		</collision>
		<visual>
			<origin rpy="0.00000 0.34897 0.00000" xyz="-0.00570 -0.04960 -0.01210"/>
			<geometry>
				<box size="0.12000 0.21400 0.04800"/>
				<!-- <box size="0.16000 0.31400 0.04800"/> -->
				<!-- <sphere radius="0.08"/> -->
			</geometry>
		</visual>
	</link>
	<link name="lowerback">
		<inertial>
			<origin rpy="0.00000 -0.00000 0.00000" xyz="0.00000 0.00000 0.00000"/>
			<mass value="0.001"/>
			<inertia ixx="0.001" ixy="0" ixz="0" iyy="0.001" iyz="0" izz="0.001"/>
		</inertial>
	</link>
	<link name="link1_25">
		<inertial>
			<origin rpy="0.00000 -0.00000 0.00000" xyz="0.00000 0.00000 0.00000"/>
			<mass value="0.001"/>
			<inertia ixx="0.001" ixy="0" ixz="0" iyy="0.001" iyz="0" izz="0.001"/>
		</inertial>
	</link>
	<link name="link1_26">
		<inertial>
			<origin rpy="0.00000 -0.00000 0.00000" xyz="0.00000 0.00000 0.00000"/>
			<mass value="0.001"/>
			<inertia ixx="0.001" ixy="0" ixz="0" iyy="0.001" iyz="0" izz="0.001"/>
		</inertial>
	</link>
	<link name="upperback">
		<inertial>
			<origin rpy="0.00000 -0.00000 0.00000" xyz="0.00000 0.00000 0.00000"/>
			<mass value="1.43675504"/>
			<inertia ixx="0.00469" ixy="0" ixz="0" iyy="0.00469" iyz="0" izz="0.00469"/>
		</inertial>
		<!-- <collision>
			<origin rpy="0.00000 -0.00000 0.00000" xyz="0.00000 0.00000 0.01000"/>
			<geometry>
				<sphere radius="0.07000"/>
			</geometry>
		</collision> -->
		<visual>
			<origin rpy="0.00000 -0.00000 0.00000" xyz="0.00000 0.00000 0.01000"/>
			<geometry>
				<sphere radius="0.07000"/>
			</geometry>
		</visual>
	</link>
	<link name="thorax">
		<inertial>
			<origin rpy="0.00000 -0.00000 0.00000" xyz="0.00000 0.00000 0.00000"/>
			<mass value="4.1887902"/>
			<inertia ixx="0.02793" ixy="0" ixz="0" iyy="0.02793" iyz="0" izz="0.02793"/>
		</inertial>
		<collision>
			<origin rpy="0.00000 -0.00000 0.00000" xyz="0.00000 0.00000 0.05400"/>
			<geometry>
				<sphere radius="0.10000"/>
			</geometry>
		</collision>
		<visual>
			<origin rpy="0.00000 -0.00000 0.00000" xyz="0.00000 0.00000 0.05400"/>
			<geometry>
				<sphere radius="0.10000"/>
			</geometry>
		</visual>
	</link>
	<link name="link1_30">
		<inertial>
			<origin rpy="0.00000 -0.00000 0.00000" xyz="0.00000 0.00000 0.00000"/>
			<mass value="0.001"/>
			<inertia ixx="0.001" ixy="0" ixz="0" iyy="0.001" iyz="0" izz="0.001"/>
		</inertial>
	</link>
	<link name="link1_31">
		<inertial>
			<origin rpy="0.00000 -0.00000 0.00000" xyz="0.00000 0.00000 0.00000"/>
			<mass value="0.001"/>
			<inertia ixx="0.001" ixy="0" ixz="0" iyy="0.001" iyz="0" izz="0.001"/>
		</inertial>
	</link>
	<link name="lowerneck">
		<inertial>
			<origin rpy="0.00000 -0.00000 0.00000" xyz="0.00000 0.00000 0.00000"/>
			<mass value="2.14466"/>
			<inertia ixx="0.00915" ixy="0" ixz="0" iyy="0.00915" iyz="0" izz="0.00915"/>
		</inertial>
		<collision>
			<origin rpy="0.00000 -0.00000 0.00000" xyz="-0.00330 -0.01070 0.20650"/>
			<geometry>
				<sphere radius="0.08000"/>
			</geometry>
		</collision>
		<visual>
			<origin rpy="0.00000 -0.00000 0.00000" xyz="-0.00330 -0.01070 0.20650"/>
			<geometry>
				<sphere radius="0.08000"/>
			</geometry>
		</visual>
	</link>
	<link name="upperneck">
		<inertial>
			<origin rpy="0.00000 -0.00000 0.00000" xyz="0.00000 0.00000 0.00000"/>
			<mass value="0.001"/>
			<inertia ixx="0.001" ixy="0" ixz="0" iyy="0.001" iyz="0" izz="0.001"/>
		</inertial>
	</link>
	<link name="head">
		<inertial>
			<origin rpy="0.00000 -0.00000 0.00000" xyz="0.00000 0.00000 0.00000"/>
			<mass value="0.001"/>
			<inertia ixx="0.001" ixy="0" ixz="0" iyy="0.001" iyz="0" izz="0.001"/>
		</inertial>
	</link>
	<link name="link1_36">
		<inertial>
			<origin rpy="0.00000 -0.00000 0.00000" xyz="0.00000 0.00000 0.00000"/>
			<mass value="0.001"/>
			<inertia ixx="0.001" ixy="0" ixz="0" iyy="0.001" iyz="0" izz="0.001"/>
		</inertial>
	</link>
	<link name="lclavicle">
		<inertial>
			<origin rpy="0.00000 -0.00000 0.00000" xyz="0.00000 0.00000 0.00000"/>
			<mass value="0.6953470866192378"/>
			<inertia ixx="0.00091" ixy="0" ixz="0" iyy="0.00388" iyz="0" izz="0.00372"/>
		</inertial>
		<!-- <collision>
			<origin rpy="-0.32719 -1.45991 0.29330" xyz="0.09065 -0.00330 -0.00955"/>
			<geometry>
				<capsule length="0.15747" radius="0.03400"/>
			</geometry>
		</collision> -->
		<visual>
			<origin rpy="-0.32719 -1.45991 0.29330" xyz="0.09065 -0.00330 -0.00955"/>
			<geometry>
				<capsule length="0.15747" radius="0.03400"/>
			</geometry>
		</visual>
	</link>
	<link name="link1_39">
		<inertial>
			<origin rpy="0.00000 -0.00000 0.00000" xyz="0.00000 0.00000 0.00000"/>
			<mass value="0.001"/>
			<inertia ixx="0.001" ixy="0" ixz="0" iyy="0.001" iyz="0" izz="0.001"/>
		</inertial>
	</link>
	<link name="link1_40">
		<inertial>
			<origin rpy="0.00000 -0.00000 0.00000" xyz="0.00000 0.00000 0.00000"/>
			<mass value="0.001"/>
			<inertia ixx="0.001" ixy="0" ixz="0" iyy="0.001" iyz="0" izz="0.001"/>
		</inertial>
	</link>
	<link name="lhumerus">
		<inertial>
			<origin rpy="0.00000 -0.00000 0.00000" xyz="0.00000 0.00000 0.00000"/>
			<mass value="0.8359806325536322"/>
			<inertia ixx="0.00056" ixy="0" ixz="0" iyy="0.00713" iyz="0" izz="0.00713"/>
		</inertial>
		<!-- <collision>
			<origin rpy="0.00000 -1.57080 0.00000" xyz="0.14045 0.00000 0.00000"/>
			<geometry>
				<capsule length="0.24590" radius="0.03100"/>
			</geometry>
		</collision> -->
		<visual>
			<origin rpy="0.00000 -1.57080 0.00000" xyz="0.14045 0.00000 0.00000"/>
			<geometry>
				<capsule length="0.24590" radius="0.03100"/>
			</geometry>
		</visual>
	</link>
	<link name="lradius">
		<inertial>
			<origin rpy="0.00000 -0.00000 0.00000" xyz="0.00000 0.00000 0.00000"/>
			<mass value="0.3976078202199582"/>
			<inertia ixx="0.00017" ixy="0" ixz="0" iyy="0.00187" iyz="0" izz="0.00187"/>
		</inertial>
		<!-- <collision>
			<origin rpy="0.00000 -1.57080 0.00000" xyz="0.08875 0.00000 0.00000"/>
			<geometry>
				<capsule length="0.17750" radius="0.02500"/>
			</geometry>
		</collision> -->
		<visual>
			<origin rpy="0.00000 -1.57080 0.00000" xyz="0.08875 0.00000 0.00000"/>
			<geometry>
				<capsule length="0.17750" radius="0.02500"/>
			</geometry>
		</visual>
	</link>
	<link name="lwrist">
		<inertial>
			<origin rpy="0.00000 -0.00000 0.00000" xyz="0.00000 0.00000 0.00000"/>
			<mass value="0.26808257310632905"/>
			<inertia ixx="0.00029" ixy="0" ixz="0" iyy="0.00029" iyz="0" izz="0.00029"/>
		</inertial>
		<collision>
			<origin rpy="0.00000 -0.00000 0.00000" xyz="0.04400 0.00000 0.00000"/>
			<geometry>
				<sphere radius="0.04000"/>
			</geometry>
		</collision>
		<visual>
			<origin rpy="0.00000 -0.00000 0.00000" xyz="0.04400 0.00000 0.00000"/>
			<geometry>
				<sphere radius="0.04000"/>
			</geometry>
		</visual>
	</link>
	<link name="link1_46">
		<inertial>
			<origin rpy="0.00000 -0.00000 0.00000" xyz="0.00000 0.00000 0.00000"/>
			<mass value="0.001"/>
			<inertia ixx="0.001" ixy="0" ixz="0" iyy="0.001" iyz="0" izz="0.001"/>
		</inertial>
	</link>
	<link name="rclavicle">
		<inertial>
			<origin rpy="0.00000 -0.00000 0.00000" xyz="0.00000 0.00000 0.00000"/>
			<mass value="0.6953470866192378"/>
			<inertia ixx="0.00091" ixy="0" ixz="0" iyy="0.00388" iyz="0" izz="0.00372"/>
		</inertial>
		<!-- <collision>
			<origin rpy="-0.32719 1.45991 -0.29330" xyz="-0.09065 -0.00330 -0.00955"/>
			<geometry>
				<capsule length="0.15747" radius="0.03400"/>
			</geometry>
		</collision> -->
		<visual>
			<origin rpy="-0.32719 1.45991 -0.29330" xyz="-0.09065 -0.00330 -0.00955"/>
			<geometry>
				<capsule length="0.15747" radius="0.03400"/>
			</geometry>
		</visual>
	</link>
	<link name="link1_49">
		<inertial>
			<origin rpy="0.00000 -0.00000 0.00000" xyz="0.00000 0.00000 0.00000"/>
			<mass value="0.001"/>
			<inertia ixx="0.001" ixy="0" ixz="0" iyy="0.001" iyz="0" izz="0.001"/>
		</inertial>
	</link>
	<link name="link1_50">
		<inertial>
			<origin rpy="0.00000 -0.00000 0.00000" xyz="0.00000 0.00000 0.00000"/>
			<mass value="0.001"/>
			<inertia ixx="0.001" ixy="0" ixz="0" iyy="0.001" iyz="0" izz="0.001"/>
		</inertial>
	</link>
	<link name="rhumerus">
		<inertial>
			<origin rpy="0.00000 -0.00000 0.00000" xyz="0.00000 0.00000 0.00000"/>
			<mass value="0.8359806325536322"/>
			<inertia ixx="0.00056" ixy="0" ixz="0" iyy="0.00713" iyz="0" izz="0.00713"/>
		</inertial>
		<!-- <collision>
			<origin rpy="0.00000 1.57080 -0.00000" xyz="-0.14045 0.00000 0.00000"/>
			<geometry>
				<capsule length="0.24590" radius="0.03100"/>
			</geometry>
		</collision> -->
		<visual>
			<origin rpy="0.00000 1.57080 -0.00000" xyz="-0.14045 0.00000 0.00000"/>
			<geometry>
				<capsule length="0.24590" radius="0.03100"/>
			</geometry>
		</visual>
	</link>
	<link name="rradius">
		<inertial>
			<origin rpy="0.00000 -0.00000 0.00000" xyz="0.00000 0.00000 0.00000"/>
			<mass value="0.3976078202199582"/>
			<inertia ixx="0.00017" ixy="0" ixz="0" iyy="0.00187" iyz="0" izz="0.00187"/>
		</inertial>
		<!-- <collision>
			<origin rpy="0.00000 1.57080 -0.00000" xyz="-0.08875 0.00000 0.00000"/>
			<geometry>
				<capsule length="0.17750" radius="0.02500"/>
			</geometry>
		</collision> -->
		<visual>
			<origin rpy="0.00000 1.57080 -0.00000" xyz="-0.08875 0.00000 0.00000"/>
			<geometry>
				<capsule length="0.17750" radius="0.02500"/>
			</geometry>
		</visual>
	</link>
	<link name="rwrist">
		<inertial>
			<origin rpy="0.00000 -0.00000 0.00000" xyz="0.00000 0.00000 0.00000"/>
			<mass value="0.26808"/>
			<inertia ixx="0.00029" ixy="0" ixz="0" iyy="0.00029" iyz="0" izz="0.00029"/>
		</inertial>
		<collision>
			<origin rpy="0.00000 -0.00000 0.00000" xyz="-0.04400 0.00000 0.00000"/>
			<geometry>
				<sphere radius="0.04000"/>
			</geometry>
		</collision>
		<visual>
			<origin rpy="0.00000 -0.00000 0.00000" xyz="-0.04400 0.00000 0.00000"/>
			<geometry>
				<sphere radius="0.04000"/>
			</geometry>
		</visual>
	</link>

	<joint name="root_pitch" type="prismatic">
		<parent link="world"/>
		<child link="aux_pitch"/>
		<dynamics damping="0.0" friction="0.0"/>
		<origin rpy="0.00000 -0.00000 0.00000" xyz="0.00000 0.00000 0.00000"/>
		<axis xyz="1.0 0.0 0.0"/>
		<limit effort="0" velocity="100.0" lower="-100" upper="100"/>
	</joint>
	<joint name="root_roll" type="prismatic">
		<parent link="aux_pitch"/>
		<child link="aux_roll"/>
		<dynamics damping="0.0" friction="0.0"/>
		<origin rpy="0.00000 -0.00000 0.00000" xyz="0.00000 0.00000 0.00000"/>
		<axis xyz="0.0 1.0 0.0"/>
		<limit effort="0" velocity="100.0" lower="-100" upper="100"/>
	</joint>
	<joint name="root_yaw" type="prismatic">
		<parent link="aux_roll"/>
		<child link="aux_yaw"/>
		<dynamics damping="0.0" friction="0.0"/>
		<origin rpy="0.00000 -0.00000 0.00000" xyz="0.00000 0.00000 0.00000"/>
		<axis xyz="0.0 0.0 1.0"/>
		<limit effort="0" velocity="100.0" lower="-100" upper="100"/>
	</joint>
	<joint name="root_x" type="revolute">
		<parent link="aux_yaw"/>
		<child link="aux_x"/>
		<dynamics damping="0.0" friction="0.0"/>
		<origin rpy="0.00000 -0.00000 0.00000" xyz="0.00000 0.00000 0.00000"/>
		<axis xyz="1.0 0.0 0.0"/>
		<limit effort="0" velocity="100.0" lower="-100" upper="100"/>
	</joint>
	<joint name="root_y" type="revolute">
		<parent link="aux_x"/>
		<child link="aux_y"/>
		<dynamics damping="0.0" friction="0.0"/>
		<origin rpy="0.00000 -0.00000 0.00000" xyz="0.00000 0.00000 0.00000"/>
		<axis xyz="0.0 1.0 0.0"/>
		<limit effort="0" velocity="100.0" lower="-100" upper="100"/>
	</joint>
	<joint name="root_z" type="revolute">
		<parent link="aux_y"/>
		<child link="root"/>
		<dynamics damping="0.0" friction="0.0"/>
		<origin rpy="0.00000 -0.00000 0.00000" xyz="0.00000 0.00000 0.00000"/>
		<axis xyz="0.0 0.0 1.0"/>
		<limit effort="0" velocity="100.0" lower="-100" upper="100"/>
	</joint>
	<joint name="jointfix_3_0" type="fixed">
		<parent link="root"/>
		<child link="lhipjoint"/>
		<dynamics damping="0.0" friction="0.000"/>
		<origin rpy="0.00000 -0.00000 0.00000" xyz="0.00000 0.00000 0.00000"/>
		<axis xyz="0.00000 0.00000 0.00000"/>
	</joint>
	<joint name="lfemur_z" type="revolute" >
		<parent link="lhipjoint"/>
		<child link="link1_3"/>
		<dynamics damping="1.0" friction="0.0001"/>
		<origin rpy="0.00000 -0.00000 0.00000" xyz="0.09630 -0.04940 -0.09180"/>
		<axis xyz="0.00000 -1.00000 0.00000"/>
		<limit effort="0" velocity="100.0" lower="-1.05" upper="1.22"/>
	</joint>
	<joint name="lfemur_y" type="revolute" >
		<parent link="link1_3"/>
		<child link="link1_4"/>
		<dynamics damping="1.0" friction="0.0001"/>
		<origin rpy="0.00000 -0.00000 0.00000" xyz="0.00000 0.00000 0.00000"/>
		<axis xyz="-0.34200 0.00000 0.93970"/>
		<limit effort="0" velocity="100.0" lower="-1.22" upper="1.22"/>
	</joint>
	<joint name="lfemur_x" type="revolute" >
		<parent link="link1_4"/>
		<child link="lfemur"/>
		<dynamics damping="1.0" friction="0.0001"/>
		<origin rpy="0.00000 -0.00000 0.00000" xyz="0.00000 0.00000 0.00000"/>
		<axis xyz="0.93970 0.00000 0.34200"/>
		<limit effort="0" velocity="100.0" lower="-2.79" upper="0.349"/>
	</joint>
	<joint name="ltibia_x" type="revolute" >
		<parent link="lfemur"/>
		<child link="ltibia"/>
		<dynamics damping="1.0" friction="0.0001"/>
		<origin rpy="0.00000 -0.00000 0.00000" xyz="0.13110 0.00000 -0.36030"/>
		<axis xyz="0.93970 0.00000 0.34200"/>
		<limit effort="0" velocity="100.0" lower="-0.2" upper="2.97"/>
	</joint>
	<joint name="lfoot_z" type="revolute" >
		<parent link="ltibia"/>
		<child link="link1_9"/>
		<dynamics damping="1.0" friction="0.0001"/>
		<origin rpy="0.00000 -0.00000 0.00000" xyz="0.13830 0.00000 -0.38000"/>
		<axis xyz="-0.34200 0.00000 0.93970"/>
		<limit effort="0" velocity="100.0" lower="-0.349" upper="1.22"/>
	</joint>
	<joint name="lfoot_y" type="revolute" >
		<parent link="link1_9"/>
		<child link="link1_10"/>
		<dynamics damping="1.0" friction="0.0001"/>
		<origin rpy="0.00000 -0.00000 0.00000" xyz="0.00000 0.00000 0.00000"/>
		<axis xyz="0.00000 -1.00000 0.00000"/>
		<limit effort="0" velocity="100.0" lower="-0.785" upper="0.785"/>
	</joint>
	<joint name="lfoot_x" type="revolute" >
		<parent link="link1_10"/>
		<child link="lfoot"/>
		<dynamics damping="1.0" friction="0.0001"/>
		<origin rpy="0.00000 -0.00000 0.00000" xyz="0.00000 0.00000 0.00000"/>
		<axis xyz="0.93970 0.00000 0.34200"/>
		<limit effort="0" velocity="100.0" lower="-0.785" upper="1.57"/>
	</joint>
	<joint name="jointfix_7_0" type="fixed">
		<parent link="root"/>
		<child link="rhipjoint"/>
		<origin rpy="0.00000 -0.00000 0.00000" xyz="0.00000 0.00000 0.00000"/>
		<axis xyz="0.00000 0.00000 0.00000"/>
	</joint>
	<joint name="rfemur_z" type="revolute" >
		<parent link="rhipjoint"/>
		<child link="link1_14"/>
		<dynamics damping="1.0" friction="0.0001"/>
		<origin rpy="0.00000 -0.00000 0.00000" xyz="-0.09630 -0.04940 -0.09180"/>
		<axis xyz="0.00000 -1.00000 0.00000"/>
		<limit effort="0" velocity="100.0" lower="-1.22" upper="1.05"/>
	</joint>
	<joint name="rfemur_y" type="revolute" >
		<parent link="link1_14"/>
		<child link="link1_15"/>
		<dynamics damping="1.0" friction="0.0001"/>
		<origin rpy="0.00000 -0.00000 0.00000" xyz="0.00000 0.00000 0.00000"/>
		<axis xyz="0.34200 0.00000 0.93970"/>
		<limit effort="0" velocity="100.0" lower="-1.22" upper="1.22"/>
	</joint>
	<joint name="rfemur_x" type="revolute" >
		<parent link="link1_15"/>
		<child link="rfemur"/>
		<dynamics damping="1.0" friction="0.0001"/>
		<origin rpy="0.00000 -0.00000 0.00000" xyz="0.00000 0.00000 0.00000"/>
		<axis xyz="0.93970 0.00000 -0.34200"/>
		<limit effort="0" velocity="100.0" lower="-2.79" upper="0.349"/>
	</joint>
	<joint name="rtibia_x" type="revolute" >
		<parent link="rfemur"/>
		<child link="rtibia"/>
		<dynamics damping="1.0" friction="0.0001"/>
		<origin rpy="0.00000 -0.00000 0.00000" xyz="-0.13110 0.00000 -0.36030"/>
		<axis xyz="0.93970 0.00000 -0.34200"/>
		<limit effort="0" velocity="100.0" lower="-0.2" upper="2.97"/>
	</joint>
	<joint name="rfoot_z" type="revolute" >
		<parent link="rtibia"/>
		<child link="link1_20"/>
		<dynamics damping="1.0" friction="0.0001"/>
		<origin rpy="0.00000 -0.00000 0.00000" xyz="-0.13830 0.00000 -0.38000"/>
		<axis xyz="0.34200 0.00000 0.93970"/>
		<limit effort="0" velocity="100.0" lower="-0.349" upper="1.22"/>
	</joint>
	<joint name="rfoot_y" type="revolute" >
		<parent link="link1_20"/>
		<child link="link1_21"/>
		<dynamics damping="1.0" friction="0.0001"/>
		<origin rpy="0.00000 -0.00000 0.00000" xyz="0.00000 0.00000 0.00000"/>
		<axis xyz="0.00000 -1.00000 0.00000"/>
		<limit effort="0" velocity="100.0" lower="-0.785" upper="0.785"/>
	</joint>
	<joint name="rfoot_x" type="revolute" >
		<parent link="link1_21"/>
		<child link="rfoot"/>
		<dynamics damping="1.0" friction="0.0001"/>
		<origin rpy="0.00000 -0.00000 0.00000" xyz="0.00000 0.00000 0.00000"/>
		<axis xyz="0.93970 0.00000 -0.34200"/>
		<limit effort="0" velocity="100.0" lower="-0.785" upper="1.57"/>
	</joint>
	<joint name="jointfix_21_0" type="fixed">
		<parent link="root"/>
		<child link="lowerback"/>
		<origin rpy="0.00000 -0.00000 0.00000" xyz="0.00000 0.00000 0.00000"/>
		<axis xyz="0.00000 0.00000 0.00000"/>
	</joint>
	<joint name="upperback_z" type="revolute" >
		<parent link="lowerback"/>
		<child link="link1_25"/>
		<dynamics damping="1.0" friction="0.0001"/>
		<origin rpy="0.00000 -0.00000 0.00000" xyz="0.00060 0.00810 0.11320"/>
		<axis xyz="0.00000 -1.00000 0.00000"/>
		<limit effort="0" velocity="100.0" lower="-0.524" upper="0.524"/>
	</joint>
	<joint name="upperback_y" type="revolute" >
		<parent link="link1_25"/>
		<child link="link1_26"/>
		<dynamics damping="1.0" friction="0.0001"/>
		<origin rpy="0.00000 -0.00000 0.00000" xyz="0.00000 0.00000 0.00000"/>
		<axis xyz="0.00000 0.00000 1.00000"/>
		<limit effort="0" velocity="100.0" lower="-0.524" upper="0.524"/>
	</joint>
	<joint name="upperback_x" type="revolute" >
		<parent link="link1_26"/>
		<child link="upperback"/>
		<dynamics damping="1.0" friction="0.0001"/>
		<origin rpy="0.00000 -0.00000 0.00000" xyz="0.00000 0.00000 0.00000"/>
		<axis xyz="1.00000 0.00000 0.00000"/>
		<limit effort="0" velocity="100.0" lower="-0.349" upper="0.785"/>
	</joint>
	<joint name="jointfix_19_24" type="fixed">
		<parent link="upperback"/>
		<child link="thorax"/>
		<origin rpy="0.00000 -0.00000 0.00000" xyz="0.00050 -0.00100 0.11360"/>
		<axis xyz="0.00000 0.00000 0.00000"/>
	</joint>
	<joint name="lowerneck_z" type="revolute" >
		<parent link="thorax"/>
		<child link="link1_30"/>
		<dynamics damping="1.0" friction="0.0001"/>
		<origin rpy="0.00000 -0.00000 0.00000" xyz="-0.00010 -0.00470 0.11390"/>
		<axis xyz="0.00000 -1.00000 0.00000"/>
		<limit effort="0" velocity="100.0" lower="-0.524" upper="0.524"/>
	</joint>
	<joint name="lowerneck_y" type="revolute" >
		<parent link="link1_30"/>
		<child link="link1_31"/>
		<dynamics damping="1.0" friction="0.0001"/>
		<origin rpy="0.00000 -0.00000 0.00000" xyz="0.00000 0.00000 0.00000"/>
		<axis xyz="0.00000 0.00000 1.00000"/>
		<limit effort="0" velocity="100.0" lower="-0.524" upper="0.524"/>
	</joint>
	<joint name="lowerneck_x" type="revolute" >
		<parent link="link1_31"/>
		<child link="lowerneck"/>
		<dynamics damping="1.0" friction="0.0001"/>
		<origin rpy="0.00000 -0.00000 0.00000" xyz="0.00000 0.00000 0.00000"/>
		<axis xyz="1.00000 0.00000 0.00000"/>
		<limit effort="0" velocity="100.0" lower="-0.349" upper="0.785"/>
	</joint>
	<joint name="jointfix_9_29" type="fixed">
		<parent link="lowerneck"/>
		<child link="upperneck"/>
		<origin rpy="0.00000 -0.00000 0.00000" xyz="-0.00330 -0.01070 0.09050"/>
		<axis xyz="0.00000 0.00000 0.00000"/>
	</joint>
	<joint name="jointfix_8_33" type="fixed">
		<parent link="upperneck"/>
		<child link="head"/>
		<origin rpy="0.00000 -0.00000 0.00000" xyz="0.00100 0.00450 0.09000"/>
		<axis xyz="0.00000 0.00000 0.00000"/>
	</joint>
	<joint name="lclavicle_z" type="revolute" >
		<parent link="lowerneck"/>
		<child link="link1_36"/>
		<dynamics damping="1.0" friction="0.0001"/>
		<origin rpy="0.00000 -0.00000 0.00000" xyz="0.00000 0.00000 0.00000"/>
		<axis xyz="0.00000 -1.00000 0.00000"/>
		<limit effort="0" velocity="100.0" lower="-0.2" upper="0.349"/>
	</joint>
	<joint name="lclavicle_y" type="revolute" >
		<parent link="link1_36"/>
		<child link="lclavicle"/>
		<dynamics damping="1.0" friction="0.0001"/>
		<origin rpy="0.00000 -0.00000 0.00000" xyz="-0.00330 -0.01070 0.09050"/>
		<axis xyz="0.00000 0.00000 1.00000"/>
		<limit effort="0" velocity="100.0" lower="-0.349" upper="0.174"/>
	</joint>
	<joint name="lhumerus_z" type="revolute" >
		<parent link="lclavicle"/>
		<child link="link1_39"/>
		<dynamics damping="1.0" friction="0.0001"/>
		<origin rpy="0.00000 -0.00000 0.00000" xyz="0.18130 -0.00660 -0.01910"/>
		<axis xyz="0.00000 0.86602 -0.50001"/>
		<limit effort="0" velocity="100.0" lower="-1.57" upper="1.57"/>
	</joint>
	<joint name="lhumerus_y" type="revolute" >
		<parent link="link1_39"/>
		<child link="link1_40"/>
		<dynamics damping="1.0" friction="0.0001"/>
		<origin rpy="0.00000 -0.00000 0.00000" xyz="0.00000 0.00000 0.00000"/>
		<axis xyz="-1.00000 0.00000 0.00000"/>
		<limit effort="0" velocity="100.0" lower="-1.57" upper="1.57"/>
	</joint>
	<joint name="lhumerus_x" type="revolute" >
		<parent link="link1_40"/>
		<child link="lhumerus"/>
		<dynamics damping="1.0" friction="0.0001"/>
		<origin rpy="0.00000 -0.00000 0.00000" xyz="0.00000 0.00000 0.00000"/>
		<axis xyz="0.00000 -0.50001 -0.86602"/>
		<limit effort="0" velocity="100.0" lower="-1.05" upper="1.57"/>
	</joint>
	<joint name="lradius_x" type="revolute" >
		<parent link="lhumerus"/>
		<child link="lradius"/>
		<dynamics damping="1.0" friction="0.0001"/>
		<origin rpy="0.00000 -0.00000 0.00000" xyz="0.28090 0.00000 0.00000"/>
		<axis xyz="0.00000 -0.50001 -0.86602"/>
		<limit effort="0" velocity="100.0" lower="-0.174" upper="2.97"/>
	</joint>
	<joint name="jointfix_10_42" type="fixed">
		<parent link="lradius"/>
		<child link="lwrist"/>
		<origin rpy="0.00000 -0.00000 0.00000" xyz="0.17750 0.00000 0.00000"/>
		<axis xyz="0.00000 0.00000 0.00000"/>
	</joint>
	<joint name="rclavicle_z" type="revolute" >
		<parent link="lowerneck"/>
		<child link="link1_46"/>
		<dynamics damping="1.0" friction="0.0001"/>
		<origin rpy="0.00000 -0.00000 0.00000" xyz="-0.00200 0.00000 0.00000"/>
		<axis xyz="0.00000 -1.00000 0.00000"/>
		<limit effort="0" velocity="100.0" lower="-0.349" upper="0.2"/>
	</joint>
	<joint name="rclavicle_y" type="revolute" >
		<parent link="link1_46"/>
		<child link="rclavicle"/>
		<dynamics damping="1.0" friction="0.0001"/>
		<origin rpy="0.00000 -0.00000 0.00000" xyz="0.00330 -0.01070 0.09050"/>
		<axis xyz="0.00000 0.00000 1.00000"/>
		<limit effort="0" velocity="100.0" lower="-0.174" upper="0.349"/>
	</joint>
	<joint name="rhumerus_z" type="revolute" >
		<parent link="rclavicle"/>
		<child link="link1_49"/>
		<dynamics damping="1.0" friction="0.0001"/>
		<origin rpy="0.00000 -0.00000 0.00000" xyz="-0.18130 -0.00660 -0.01910"/>
		<axis xyz="0.00000 0.86602 -0.50001"/>
		<limit effort="0" velocity="100.0" lower="-1.57" upper="1.57"/>
	</joint>
	<joint name="rhumerus_y" type="revolute" >
		<parent link="link1_49"/>
		<child link="link1_50"/>
		<dynamics damping="1.0" friction="0.0001"/>
		<origin rpy="0.00000 -0.00000 0.00000" xyz="0.00000 0.00000 0.00000"/>
		<axis xyz="1.00000 0.00000 0.00000"/>
		<limit effort="0" velocity="100.0" lower="-1.57" upper="1.57"/>
	</joint>
	<joint name="rhumerus_x" type="revolute" >
		<parent link="link1_50"/>
		<child link="rhumerus"/>
		<dynamics damping="1.0" friction="0.0001"/>
		<origin rpy="0.00000 -0.00000 0.00000" xyz="0.00000 0.00000 0.00000"/>
		<axis xyz="0.00000 0.50001 0.86602"/>
		<limit effort="0" velocity="100.0" lower="-1.57" upper="1.05"/>
	</joint>
	<joint name="rradius_x" type="revolute" >
		<parent link="rhumerus"/>
		<child link="rradius"/>
		<dynamics damping="1.0" friction="0.0001"/>
		<origin rpy="0.00000 -0.00000 0.00000" xyz="-0.28090 0.00000 0.00000"/>
		<axis xyz="0.00000 0.50001 0.86602"/>
		<limit effort="0" velocity="100.0" lower="-0.174" upper="2.97"/>
	</joint>
	<joint name="jointfix_14_52" type="fixed">
		<parent link="rradius"/>
		<child link="rwrist"/>
		<origin rpy="0.00000 -0.00000 0.00000" xyz="-0.17750 0.00000 0.00000"/>
		<axis xyz="0.00000 0.00000 0.00000"/>
	</joint>
</robot>
